Workbook

Sheet Dashboard
B2: DASHBOARD
B6: ="Demography by "&Analysis!K5 -> Demography by Active | Q6: EMR Active | U6: ="Demography by "&Analysis!R5&" from "&TEXT(Analysis!R8,"dd/mm/yy")&" to "&TEXT(Analysis!R10,"dd/mm/yy") -> Demography by Lost to followup from 01/10/24 to 30/09/25
Q8: =Analysis!I18 -> 1887
Q12: Calculated TX_CURR
Q14: =Analysis!AK20 -> 1898
Q17: NDR Active
Q20: =Analysis!I19 -> 1901
B29: Biometrics Analysis
B49: Retention Analysis

Sheet Analysis
E1: Demography | T1: Biometrics Analysis | AM1: QUARTERLY DATA
A2: Timelines | F2: Demography By Status | M2: Demography By Exit Status | W2: Biometric Capture | AD2: PBS Recapture | BC2: Q4 FY26 TXCUR | BD2: 1937
B3: Report Date | C3: 45968 | F3: Sex | G3: M | H3: F | I3: Total | K3: Select Status | M3: Sex | N3: M | O3: F | P3: Total | R3: Select Status | W3: Sex | X3: M | Y3: F | Z3: Total | AD3: Sex | AE3: M | AF3: F | AG3: Total | AI3: NDR | AJ3: Biometrics | AK3: Count | AL3: %
A4: Week | B4: Start Date | C4: 46124 | F4: <5 | G4: 3 | H4: 1 | I4: 4 | K4: ART Status | M4: <5 | N4: 0 | O4: 0 | P4: 0 | R4: ART Status | W4: <5 | X4: 2 | Y4: 0 | Z4: 2 | AB4: Select Status | AD4: <5 | AE4: 2 | AF4: 0 | AG4: 2 | AJ4: Active | AK4: 1901 | AN4: QUARTERLY | AO4: Month | AP4: Week | AQ4: HTS_TST | AR4: HTS_POS | AS4: TX_NEW | AT4: TRANSFER_IN | AU4: TRANSFER OUT | AV4: IIT (Quarterly cummulative) | AW4: %IIT | AX4: LIHMIS | AY4: DPU | AZ4: VLSC | BA4: RESULTS | BB4: TX_CUR | BC4: Calculated TX_CUR | BD4: NDR TX_CUR
B5: End Date | C5: 46129 | F5: 5-9 | G5: 4 | H5: 6 | I5: 10 | K5: Active | M5: 5-9 | N5: 0 | O5: 0 | P5: 0 | R5: Lost to followup | W5: 5-9 | X5: 4 | Y5: 6 | Z5: 10 | AB5: ART Status | AD5: 5-9 | AE5: 0 | AF5: 0 | AG5: 0 | AJ5: Baseline | AK5: 1897 | AL5: 0.99789584 | AN5: Q1 | AO5: OCTOBER | AP5: Week 1 | AQ5: 5 | AR5: 0 | AS5: 0 | AT5: 0 | AU5: 0 | AV5: 0 | AW5: =AV5/$BD$5 -> 0 | AX5: 0 | AY5: 25 | AZ5: 28 | BA5: 40 | BB5: 1922 | BC5: 1934 | BD5: 1938
A6: Month | B6: Start Date | C6: 46113 | F6: 10-14 | G6: 8 | H6: 9 | I6: 17 | M6: 10-14 | N6: 0 | O6: 0 | P6: 0 | W6: 10-14 | X6: 8 | Y6: 9 | Z6: 17 | AB6: Active | AD6: 10-14 | AE6: 4 | AF6: 0 | AG6: 4 | AJ6: No Baseline | AK6: 4 | AL6: 0.0021041557 | AP6: Week 2 | AQ6: 15 | AR6: 2 | AS6: 2 | AT6: 2 | AU6: 2 | AV6: 2 | AW6: =AV6/$BD$5 -> 0.0010319917 | AX6: 0 | AY6: 54 | AZ6: 53 | BA6: 0 | BB6: 1925 | BC6: 1938 | BD6: 1941
B7: End Date | C7: 46142 | F7: 15-19 | G7: 11 | H7: 7 | I7: 18 | M7: 15-19 | N7: 1 | O7: 0 | P7: 1 | R7: Start Date | W7: 15-19 | X7: 11 | Y7: 7 | Z7: 18 | AD7: 15-19 | AE7: 3 | AF7: 2 | AG7: 5 | AJ7: Recaptured | AK7: 1874 | AL7: 0.98787559 | AP7: Week 3 | AQ7: 54 | AR7: 2 | AS7: 1 | AT7: 0 | AU7: 2 | AV7: 6 | AW7: =AV7/$BD$5 -> 0.0030959752 | AX7: 1 | AY7: 167 | AZ7: 44 | BA7: 65 | BB7: 1924 | BC7: 1940 | BD7: 1946
A8: Quarter | B8: Start Date | C8: 46113 | F8: 20-24 | G8: 8 | H8: 34 | I8: 42 | M8: 20-24 | N8: 0 | O8: 1 | P8: 1 | R8: 45566 | W8: 20-24 | X8: 8 | Y8: 34 | Z8: 42 | AB8: Select | AD8: 20-24 | AE8: 2 | AF8: 7 | AG8: 9 | AJ8: Match | AK8: 1850 | AL8: 0.98719317 | AP8: Week 4 | AQ8: 69 | AR8: 1 | AS8: 1 | AT8: 0 | AU8: 0 | AV8: 9 | AW8: =AV8/$BD$5 -> 0.0046439628 | AX8: 1 | AY8: 91 | AZ8: 20 | BA8: 0 | BB8: 1921 | BC8: 1936 | BD8: 1940
B9: End Date | C9: 46203 | F9: 25-29 | G9: 8 | H9: 80 | I9: 88 | M9: 25-29 | N9: 0 | O9: 1 | P9: 1 | R9: End Date | W9: 25-29 | X9: 8 | Y9: 80 | Z9: 88 | AB9: Captured? | AD9: 25-29 | AE9: 3 | AF9: 27 | AG9: 30 | AJ9: No Match | AK9: 24 | AL9: 0.01280683 | AP9: Week 5 | AQ9: 55 | AR9: 2 | AS9: 1 | AT9: 3 | AU9: 1 | AV9: 15 | AW9: =AV9/$BD$5 -> 0.0077399381 | AX9: 0 | AY9: 62 | AZ9: 16 | BA9: 39 | BB9: 1921 | BC9: 1936 | BD9: 1936
A10: FY | B10: Start Date | C10: 45931 | F10: 30-34 | G10: 37 | H10: 241 | I10: 278 | M10: 30-34 | N10: 1 | O10: 6 | P10: 7 | R10: 45930 | W10: 30-34 | X10: 37 | Y10: 241 | Z10: 278 | AB10: Yes | AD10: 30-34 | AE10: 17 | AF10: 102 | AG10: 119 | AJ10: Duplicates | AK10: 12 | AL10: 0.0064034152 | AO10: NOVEMBER | AP10: Week 6 | AQ10: 36 | AR10: 3 | AS10: 3 | AT10: 1 | AU10: 0 | AV10: 15 | AW10: =AV10/$BD$5 -> 0.0077399381 | AX10: 0 | AY10: 72 | AZ10: 21 | BA10: 0 | BB10: 1926 | BC10: 1942 | BD10: 1945
B11: End Date | C11: 46295 | F11: 35-39 | G11: 80 | H11: 323 | I11: 403 | M11: 35-39 | N11: 1 | O11: 1 | P11: 2 | W11: 35-39 | X11: 80 | Y11: 323 | Z11: 403 | AD11: 35-39 | AE11: 37 | AF11: 139 | AG11: 176 | AJ11: No Recapture | AK11: 27 | AL11: 0.014232999 | AP11: Week 7 | AQ11: 55 | AR11: 3 | AS11: 2 | AT11: 0 | AU11: 0 | AV11: 20 | AW11: =AV11/$BD$5 -> 0.010319917 | AX11: 5 | AY11: 180 | AZ11: 45 | BA11: 21 | BB11: 1924 | BC11: 1940 | BD11: 1940
A12: Year | B12: Start Date | C12: 45717 | F12: 40-44 | G12: 102 | H12: 275 | I12: 377 | M12: 40-44 | N12: 1 | O12: 2 | P12: 3 | W12: 40-44 | X12: 102 | Y12: 275 | Z12: 377 | AB12: Select | AD12: 40-44 | AE12: 53 | AF12: 109 | AG12: 162 | AJ12: Replaced Matched | AK12: 1264 | AL12: 0.67449306 | AP12: Week 8 | AQ12: 44 | AR12: 1 | AS12: 0 | AT12: 0 | AU12: 0 | AV12: 15 | AW12: =AV12/$BD$5 -> 0.0077399381 | AX12: 0 | AY12: 66 | AZ12: 39 | BA12: 0 | BB12: 1928 | BC12: 1943 | BD12: 1949
B13: End Date | C13: 46142 | F13: 45-49 | G13: 97 | H13: 167 | I13: 264 | M13: 45-49 | N13: 2 | O13: 2 | P13: 4 | W13: 45-49 | X13: 96 | Y13: 167 | Z13: 263 | AB13: No. Recap | AD13: 45-49 | AE13: 32 | AF13: 67 | AG13: 99 | AJ13: Replaced No Match | AK13: 21 | AL13: 0.011205977 | AP13: Week 9 | AQ13: 25 | AR13: 0 | AS13: 1 | AT13: 0 | AU13: 0 | AV13: 10 | AW13: =AV13/$BD$5 -> 0.0051599587 | AX13: 12 | AY13: 124 | AZ13: 51 | BA13: 0 | BB13: 1933 | BC13: 1947 | BD13: 1941
F14: 50-54 | G14: 78 | H14: 111 | I14: 189 | M14: 50-54 | N14: 0 | O14: 1 | P14: 1 | W14: 50-54 | X14: 78 | Y14: 111 | Z14: 189 | AB14: 2 | AD14: 50-54 | AE14: 32 | AF14: 51 | AG14: 83 | AJ14: Recaptured No Baseline | AK14: 0 | AL14: 0 | AO14: DECEMBER | AP14: Week 10 | AQ14: 56 | AR14: 1 | AS14: 2 | AT14: 0 | AU14: 0 | AV14: 8 | AW14: =AV14/$BD$5 -> 0.004127967 | AX14: 14 | AY14: 163 | AZ14: 57 | BA14: 0 | BB14: 1936 | BC14: 1945 | BD14: 1941
F15: 55-59 | G15: 53 | H15: 54 | I15: 107 | M15: 55-59 | N15: 0 | O15: 1 | P15: 1 | W15: 55-59 | X15: 53 | Y15: 54 | Z15: 107 | AD15: 55-59 | AE15: 25 | AF15: 22 | AG15: 47 | AI15: EMR | AJ15: Active | AK15: 1887 | AP15: Week 11 | AQ15: 35 | AR15: 1 | AS15: 1 | AT15: 1 | AU15: 1 | AV15: 10 | AW15: =AV15/$BD$5 -> 0.0051599587 | AX15: 15 | AY15: 125 | AZ15: 72 | BA15: 68 | BB15: 1935 | BC15: 1946 | BD15: 1941
A16: Next Week | B16: Start Date | C16: 46131 | F16: 60-64 | G16: 23 | H16: 30 | I16: 53 | M16: 60-64 | N16: 0 | O16: 0 | P16: 0 | W16: 60-64 | X16: 23 | Y16: 30 | Z16: 53 | AD16: 60-64 | AE16: 11 | AF16: 18 | AG16: 29 | AJ16: Baseline | AK16: 1884 | AL16: 0.99841017 | AP16: Week 12 | AQ16: 48 | AR16: 0 | AS16: 0 | AT16: 0 | AU16: 0 | AV16: 6 | AW16: =AV16/$BD$5 -> 0.0030959752 | AX16: 18 | AY16: 4 | AZ16: 0 | BA16: 71 | BB16: 1939 | BC16: 1951 | BD16: 1941
B17: End Date | C17: 46136 | F17: 65+ | G17: 22 | H17: 15 | I17: 37 | M17: 65+ | N17: 1 | O17: 1 | P17: 2 | W17: 65+ | X17: 22 | Y17: 15 | Z17: 37 | AD17: 65+ | AE17: 10 | AF17: 6 | AG17: 16 | AJ17: No Baseline | AK17: 3 | AL17: 0.0015898251 | AP17: Week 13 | AQ17: 0 | AR17: 0 | AS17: 2 | AT17: 0 | AU17: 0 | AV17: 0 | AW17: =AV17/$BD$5 -> 0 | AX17: 0 | AY17: 0 | AZ17: 0 | BA17: 0 | BB17: 1939 | BC17: 1951 | BD17: 1939
F18: TOTAL | G18: 534 | H18: 1353 | I18: 1887 | M18: TOTAL | N18: 7 | O18: 16 | P18: 23 | W18: TOTAL | X18: 532 | Y18: 1352 | Z18: 1884 | AD18: TOTAL | AE18: 231 | AF18: 550 | AG18: 781 | AJ18: Recaptured | AK18: 1862 | AL18: 0.98832272 | AP18: Week 14 | AQ18: 0 | AR18: 0 | AS18: 0 | AT18: 0 | AU18: 0 | AV18: 0 | AW18: =AV18/$BD$5 -> 0 | AX18: 0 | AY18: 0 | AZ18: 0 | BA18: 0 | BB18: 1939 | BC18: 1951 | BD18: 1953
H19: NDR | I19: 1901 | AJ19: No Recapture | AK19: 22 | AL19: 0.011677282 | AN19: Q2 | AO19: JANUARY | AP19: Week 15 | AQ19: 55 | AR19: 4 | AS19: 1 | AT19: 1 | AU19: 0 | AV19: 9 | AW19: =AV19/$BD$18 -> 0.0046082949 | AX19: 7 | AY19: 34 | AZ19: 15 | BA19: 0 | BB19: 1932 | BC19: 1939 | BD19: 1935
B20: Missed appt | C20: 46082 | AJ20: Calculated TX_CURR | AK20: 1898 | AP20: Week 16 | AQ20: 43 | AR20: 2 | AS20: 1 | AT20: 1 | AU20: 1 | AV20: 11 | AW20: =AV20/$BD$18 -> 0.0056323605 | AX20: 5 | AY20: 37 | AZ20: 40 | BA20: 0 | BB20: 1939 | BC20: 1947 | BD20: 1943
E21: Retention | AP21: Week 17 | AQ21: 47 | AR21: 2 | AS21: 0 | AT21: 1 | AU21: 0 | AV21: 11 | AW21: =AV21/$BD$18 -> 0.0056323605 | AX21: 0 | AY21: 40 | AZ21: 28 | BA21: 22 | BB21: 1936 | BC21: 1950 | BD21: 1952
F22: Quarter | G22: Year | H22: Month | I22: ART_New | J22: Transfer_In | K22: Transfer_Out | L22: Dead | M22: LTFU | N22: Discontinued_Care | AP22: Week 18 | AQ22: 59 | AR22: 4 | AS22: 1 | AT22: 0 | AU22: 4 | AV22: 11 | AW22: =AV22/$BD$18 -> 0.0056323605 | AX22: 4 | AY22: 68 | AZ22: 15 | BA22: 0 | BB22: 1939 | BC22: 1954 | BD22: 1952
F23: Q1 | G23: 2024 | H23: 45931 | I23: 5 | J23: 5 | K23: 6 | L23: 2 | M23: 0 | N23: 0 | R23: Active Clients | S23: 1887 | V23: Active Females | X23: 1353 | AO23: FEBRUARY | AP23: Week 19 | AQ23: 67 | AR23: 3 | AS23: 3 | AT23: 2 | AU23: 2 | AV23: 8 | AW23: =AV23/$BD$18 -> 0.0040962622 | AX23: 8 | AY23: 201 | AZ23: 34 | BA23: 0 | BB23: 1948 | BC23: 1963 | BD23: 1952
G24: 2024 | H24: 45962 | I24: 4 | J24: 0 | K24: 0 | L24: 2 | M24: 2 | N24: 0 | R24: Active Clients with Pill Balance | S24: 1889 | V24: Active Pregnant | X24: 5 | AA24: Facility Dispensing | AC24: Active No. | AE24: Community Dispensing | AG24: Active No. | AP24: Week 20 | AQ24: 44 | AR24: 2 | AS24: 1 | AT24: 0 | AU24: 1 | AV24: 7 | AW24: =AV24/$BD$18 -> 0.0035842294 | AX24: 11 | AY24: 131 | AZ24: 35 | BA24: 8 | BB24: 1950 | BC24: 1968 | BD24: 1952
G25: 2024 | H25: 45992 | I25: 4 | J25: 1 | K25: 2 | L25: 0 | M25: 1 | N25: 0 | R25: Active Previous Quarter | S25: 1898 | V25: Active Breastfeeding | X25: 14 | AA25: FBM1 | AB25: Refill Fast Track | AC25: 207 | AE25: CBM1 | AF25: Community Pharmacy | AG25: 0 | AP25: Week 21 | AQ25: 50 | AR25: 1 | AS25: 1 | AT25: 0 | AU25: 2 | AV25: 17 | AW25: =AV25/$BD$18 -> 0.0087045571 | AX25: 0 | AY25: 61 | AZ25: 53 | BA25: 18 | BB25: 1945 | BC25: 1962 | BD25: 1972
F26: Q2 | G26: 2025 | H26: 46023 | I26: 6 | J26: 3 | K26: 9 | L26: 1 | M26: 0 | N26: 0 | R26: Active (0-19yrs) | S26: 49 | AA26: FBM2 - Facility ART group HCW led | AC26: 0 | AE26: CBM2 | AF26: Community ART | AG26: 0 | AP26: Week 22 | AQ26: 32 | AR26: 1 | AS26: 0 | AT26: 0 | AU26: 0 | AV26: 16 | AW26: =AV26/$BD$18 -> 0.0081925243 | AX26: 2 | AY26: 162 | AZ26: 45 | BA26: 0 | BB26: 1948 | BC26: 1960 | BD26: 1972
G27: 2025 | H27: 46054 | I27: 9 | J27: 2 | K27: 2 | L27: 3 | M27: 3 | N27: 0 | Q27: Regimen Line | R27: Regimen | S27: Active No. | V27: Days of Refil | W27: No | AA27: FBM3 - Facility ART group Support group led | AC27: 0 | AE27: CBM3 - Community ART Refill Group PLHIV led | AG27: 0 | AO27: MARCH | AP27: Week 23 | AQ27: 50 | AR27: 2 | AS27: 1 | AT27: 1 | AU27: 1 | AV27: 3 | AW27: =AV27/$BD$18 -> 0.0015360983 | AX27: 0 | AY27: 167 | AZ27: 12 | BA27: 23 | BB27: 1950 | BC27: 1960 | BD27: 1962
G28: 2025 | H28: 46082 | I28: 11 | J28: 1 | K28: 2 | L28: 2 | M28: 1 | N28: 0 | Q28: Adult 1st line ARV regimen | R28: TDF-3TC-DTG | S28: 1837 | V28: Active <30 | W28: 0 | AA28: FBM4 - Decentralized Hub and Spoke | AC28: 0 | AE28: CBM4 - Adolescent Community ART Peer led group | AG28: 0 | AP28: Week 24 | AQ28: 51 | AR28: 5 | AS28: 2 | AT28: 1 | AU28: 5 | AV28: 31 | AW28: =AV28/$BD$18 -> 0.015873016 | AX28: 5 | AY28: 39 | AZ28: 32 | BA28: 5 | BB28: 1936 | BC28: 1949 | BD28: 1946
F29: Q3 | G29: 2025 | H29: 46113 | I29: 1 | J29: 0 | K29: 0 | L29: 0 | M29: 0 | N29: 0 | Q29: Adult 1st line ARV regimen | R29: ABC-3TC-DTG | S29: 6 | V29: Active 30 | W29: 23 | AA29: FBM5 - After hours | AC29: 0 | AE29: CBM5 | AF29: Home Delivery | AG29: 0 | AP29: Week 25 | AQ29: 31 | AR29: 3 | AS29: 3 | AT29: 0 | AU29: 2 | AV29: 29 | AW29: =AV29/$BD$18 -> 0.01484895 | AX29: 6 | AY29: 11 | AZ29: 8 | BA29: 10 | BB29: 1893 | BC29: 1908 | BD29: 1900
G30: 2025 | H30: 46143 | I30: 0 | J30: 0 | K30: 0 | L30: 0 | M30: 0 | N30: 0 | Q30: Child 1st line ARV regimen | R30: ABC-3TC-DTG | S30: 22 | V30: Active 90 | W30: 275 | AA30: FBM7 - Child/Teen/Adolescents club Peer Managed | AC30: 0 | AE30: CBM6 - OSS Community Platforms | AG30: 0 | AP30: Week 26
G31: 2025 | H31: 46174 | I31: 0 | J31: 0 | K31: 0 | L31: 0 | M31: 0 | N31: 0 | Q31: Adult 2nd line ARV regimen | R31: TDF-3TC-ATV/r | S31: 16 | V31: Active >120<150 | W31: 46 | AA31: FBM8 | AB31: Mother-infant Pair | AC31: 0 | AF31: Total | AG31: 0 | AN31: Q3 | AO31: APRIL | AP31: Week 27
F32: Q4 | G32: 2025 | H32: 46204 | I32: 0 | J32: 0 | K32: 0 | L32: 0 | M32: 0 | N32: 0 | Q32: Adult 2nd line ARV regimen | R32: TDF-3TC-LPV/r | S32: 0 | V32: Active 150 | W32: 292 | AB32: Total | AC32: 207 | AP32: Week 28
G33: 2025 | H33: 46235 | I33: 0 | J33: 0 | K33: 0 | L33: 0 | M33: 0 | N33: 0 | Q33: Adult 2nd line ARV regimen | R33: AZT-3TC-ATV/r | S33: 4 | V33: Active >150<180 | W33: 1 | AP33: Week 29
G34: 2025 | H34: 46266 | I34: 0 | J34: 0 | K34: 0 | L34: 0 | M34: 0 | N34: 0 | Q34: Adult 2nd line ARV regimen | R34: ABC-3TC-ATV/r | S34: 0 | V34: Active 180 | W34: 1204 | AP34: Week 30
F35: Total | H35: 46296 | I35: 40 | J35: 12 | K35: 21 | L35: 10 | M35: 7 | N35: 0 | Q35: Child 2nd line ARV regimen | S35: 0 | V35: Blank | W35: 0 | AP35: Week 31
R36: Total | S36: 1885 | V36: Total Active | W36: 1841 | AO36: MAY | AP36: Week 32
E37: VIRAL LOAD ANALYSIS | BQ37: Week 33
BQ38: Week 34
BQ39: Week 35
BP40: JUNE | BQ40: Week 36
...

Sheet HTS Linelist
A1: IP | B1: Facility State | C1: Facility LGA | D1: Facility | E1: DATIM Code | F1: Client State | G1: Client LGA | H1: HTSClientCode | I1: PepfarID | J1: HospID | K1: RecencyID | L1: Sex | M1: Date Of Birth | N1: CurrentAge | O1: Age Group | P1: AgeAtVisit | Q1: VisitDate | R1: Setting | S1: VisitID | T1: KindOfHTS | U1: SettingOthersSpecify | V1: FirstTimeVisit | W1: TypeOfSession | X1: ReferredFrom | Y1: MaritalStatus | Z1: NoOfOwnChildrenLessThan5 | AA1: NoOfWives | AB1: IsClientIdentifiedFromAnindexClient | AC1: IndexType | AD1: IndexClientID | AE1: IsClientRetestingForResultVerification | AF1: PreviouslyTestedHIVNegative | AG1: ClientPregnant | AH1: ClientInformedAboutHIVTransmissionRoutes | AI1: ClientInformedAboutRiskFactorsForHIVTransmission | AJ1: ClientInformedOnPreventingHIVTransmissionMethods | AK1: ClientInformedAboutPossibleTestResults | AL1: InformedConsentForHivTestingGiven | AM1: EverHadSexualIntercourse | AN1: BloodTransfusioninLast3Months | AO1: UnprotectedSexWithCasualPartnerinLast3Months | AP1: UnprotectedSexWithRegularPartnerInTheLast3Months | AQ1: STIinLast3Months | AR1: MoreThan1SexPartnerDuringLast3Months | AS1: CurrentCough | AT1: WeightLoss | AU1: Fever | AV1: NightSweats | AW1: ContactWithTBPatient | AX1: TBScreeningScore | AY1: ComplaintsofVaginalDischargeorBurningWhenUrinating | AZ1: ComplaintsofLowerAbdominalPainsWithorWithoutVaginalDischarge | BA1: ComplaintsofGenitalSoreOrSwollenInguinalLymphNodesWithorWithoutPains | BB1: STIScreeningScore | BC1: RiskAssesmentScore | BD1: ScreeningTestResult | BE1: ScreeningTestDate | BF1: ConfirmatoryTestResult | BG1: ConfirmatoryTestDate | BH1: TieBreaker | BI1: TieBreakerDate | BJ1: FinalResult | BK1: OPT Out of RTRI | BL1: Recency Test Name | BM1: Recency Test Date | BN1: Control Line | BO1: Verification Line | BP1: Longterm Line | BQ1: Recency Interpretation | BR1: HasViralLoadBeenRequested | BS1: Date Sample Collected | BT1: Date Sample Sent | BU1: Viral Load Result | BV1: Viral Load Result Classification | BW1: Date Of Viral Load Result | BX1: PCR Lab | BY1: Final Recency Result | BZ1: HaveYouBeenTestedforHivBeforeWithinThisYear | CA1: HIVRequestandResultFormSignedbyTester | CB1: ClientReceivedHIVTestResult | CC1: PostTestCounselingDone | CD1: ClientUseFPMethodsOtherThanCondom | CE1: ClientUseCondomsAsFPMethod | CF1: SyphilisTestResult | CG1: HepatitisBVirusTestResult | CH1: HepatitisCVirusTestResult | CI1: ClientReferredtoOtherServices | CJ1: RiskReductionPlanDeveloped | CK1: PostTestDisclosurePlanDeveloped | CL1: WillBringPartnerForHivTesting | CM1: WillBringOwnChildrenLessThan5YearsforHIVTesting | CN1: ProvidedWithInformationonFPandDualContraception | CO1: CorrectCondomUseDemonstrated | CP1: CondomsProvidedToClient | CQ1: AdditionalComments | CR1: SignatureDate
A2: IHVN | B2: Nasarawa | C2: Lafia | D2: na Shabu Model Comprehensive Centre | E2: ZBFgkyECWkA | F2: NASARAWA | G2: LAFIA | H2: 001/01/23/IND | I2: NAS05405547 | K2: NS08676660 | L2: F | M2: 01-Jan-1976 | N2: 49 | O2: 45 - 49 | P2: 47 | Q2: 05-Jan-2023 | R2: Other | S2: 113446 | T2: Provider-initiated HIV testing and counseling | U2: INDX | V2: Yes | W2: Individual | X2: Other | Y2: Married | Z2: 7 | AB2: Yes | AC2: Sexual | AD2: 5547 | AE2: Yes | AF2: No | AG2: No | AH2: Yes | AI2: Yes | AJ2: Yes | AK2: Yes | AL2: Yes | AM2: Yes | AN2: No | AO2: No | AP2: Yes | AQ2: No | AR2: No | AS2: No | AT2: No | AU2: Yes | AV2: No | AW2: No | AX2: 1 | AY2: No | AZ2: No | BA2: No | BB2: 0 | BC2: 2 | BD2: REACTIVE | BE2: 44931 | BF2: REACTIVE | BG2: 44931 | BJ2: Positive | BK2: No | BL2: Asante | BM2: 44931 | BN2: Yes | BO2: Yes | BP2: Yes | BQ2: Long Term | BZ2: Not previously tested | CA2: Yes | CB2: Yes | CC2: Yes | CD2: Yes | CE2: Yes | CF2: NON-REACTIVE | CG2: Negative | CH2: Negative | CI2: Yes | CJ2: Yes | CK2: Yes | CL2: Yes | CM2: Yes | CN2: Yes | CO2: Yes | CP2: Yes | CR2: 05-Jan-2023
A3: IHVN | B3: Nasarawa | C3: Lafia | D3: na Shabu Model Comprehensive Centre | E3: ZBFgkyECWkA | F3: NASARAWA | G3: LAFIA | H3: NS08670264 | I3: NAS05405548 | K3: NS08670264 | L3: M | M3: 01-Jan-1984 | N3: 41 | O3: 40 - 44 | P3: 39 | Q3: 06-Jan-2023 | R3: Other | S3: 113470 | T3: Provider-initiated HIV testing and counseling | U3: INDEX | V3: Yes | W3: Individual | X3: Other | Y3: Married | Z3: 1 | AA3: 1 | AB3: Yes | AC3: Sexual | AD3: 5548 | AE3: Yes | AF3: No | AH3: Yes | AI3: Yes | AJ3: Yes | AK3: Yes | AL3: Yes | AM3: Yes | AN3: No | AO3: No | AP3: Yes | AQ3: No | AR3: No | AS3: Yes | AT3: Yes | AU3: Yes | AV3: No | AW3: No | AX3: 3 | BA3: Yes | BB3: 1 | BC3: 2 | BD3: REACTIVE | BE3: 44932 | BF3: REACTIVE | BG3: 44932 | BJ3: Positive | BK3: No | BL3: Asante | BM3: 44932 | BN3: Yes | BO3: Yes | BP3: Yes | BQ3: Long Term | BZ3: Not previously tested | CA3: Yes | CB3: Yes | CC3: Yes | CD3: Yes | CE3: No | CF3: NON-REACTIVE | CG3: Negative | CH3: Negative | CI3: No | CJ3: Yes | CK3: No | CL3: Yes | CM3: Yes | CN3: Yes | CO3: Yes | CP3: No | CR3: 06-Jan-2023
A4: IHVN | B4: Nasarawa | C4: Lafia | D4: na Shabu Model Comprehensive Centre | E4: ZBFgkyECWkA | F4: NASARAWA | G4: LAFIA | H4: 004/1/23/IND | L4: F | M4: 01-Jan-1976 | N4: 49 | O4: 45 - 49 | P4: 47 | Q4: 05-Jan-2023 | R4: Other | S4: 113797 | T4: Provider-initiated HIV testing and counseling | U4: INDEX | V4: No | W4: Individual | X4: Other | Y4: Married | Z4: 5 | AB4: No | AE4: No | AF4: Yes | AG4: No | AH4: Yes | AI4: Yes | AJ4: Yes | AK4: Yes | AL4: Yes | AM4: Yes | AN4: No | AO4: No | AP4: Yes | AQ4: Yes | AR4: No | AS4: No | AT4: Yes | AU4: Yes | AV4: No | AW4: No | AX4: 2 | AY4: No | AZ4: Yes | BA4: No | BB4: 1 | BC4: 3 | BD4: NON-REACTIVE | BE4: 44931 | BJ4: Negative | BZ4: Previously tested negative | CA4: Yes | CB4: Yes | CC4: Yes | CD4: No | CE4: No | CI4: No | CJ4: Yes | CK4: Yes | CL4: Yes | CM4: Yes | CN4: No | CO4: No | CP4: No | CR4: 05-Jan-2023
A5: IHVN | B5: Nasarawa | C5: Lafia | D5: na Shabu Model Comprehensive Centre | E5: ZBFgkyECWkA | F5: NASARAWA | G5: LAFIA | H5: 005/1/23/IND | L5: M | M5: 01-Jan-2000 | N5: 25 | O5: 25 - 29 | P5: 23 | Q5: 05-Jan-2023 | R5: Other | S5: 113798 | T5: Provider-initiated HIV testing and counseling | U5: INDEX | V5: No | W5: Individual | X5: Other | Y5: Married | Z5: 1 | AA5: 1 | AB5: No | AE5: No | AF5: Yes | AH5: Yes | AI5: Yes | AJ5: Yes | AK5: Yes | AL5: Yes | AM5: Yes | AN5: No | AO5: No | AP5: Yes | AQ5: Yes | AR5: No | AS5: Yes | AT5: No | AU5: Yes | AV5: No | AW5: No | AX5: 2 | BA5: No | BB5: 0 | BC5: 3 | BD5: NON-REACTIVE | BE5: 44931 | BJ5: Negative | BZ5: Previously tested negative | CA5: Yes | CB5: Yes | CC5: Yes | CD5: No | CE5: No | CI5: No | CJ5: Yes | CK5: Yes | CL5: Yes | CM5: Yes | CN5: No | CO5: No | CP5: No | CR5: 05-Jan-2023
A6: IHVN | B6: Nasarawa | C6: Lafia | D6: na Shabu Model Comprehensive Centre | E6: ZBFgkyECWkA | F6: NASARAWA | G6: LAFIA | H6: 001/01/23/INP | L6: F | M6: 01-Jan-2001 | N6: 24 | O6: 20 - 24 | P6: 22 | Q6: 02-Jan-2023 | R6: Other | S6: 113799 | T6: Provider-initiated HIV testing and counseling | U6: INPATIENT | V6: Yes | W6: Individual | X6: Other | Y6: Married | Z6: 1 | AB6: No | AE6: No | AF6: No | AG6: No | AH6: Yes | AI6: Yes | AJ6: Yes | AK6: Yes | AL6: Yes | AM6: Yes | AN6: No | AO6: Yes | AP6: No | AQ6: No | AR6: Yes | AS6: No | AT6: Yes | AU6: No | AV6: No | AW6: No | AX6: 1 | AY6: No | AZ6: Yes | BA6: No | BB6: 1 | BC6: 3 | BD6: NON-REACTIVE | BE6: 44928 | BJ6: Negative | BZ6: Not previously tested | CA6: Yes | CB6: Yes | CC6: Yes | CD6: No | CE6: No | CI6: No | CJ6: Yes | CK6: Yes | CL6: Yes | CM6: No | CN6: No | CO6: No | CP6: No | CR6: 02-Jan-2023
A7: IHVN | B7: Nasarawa | C7: Lafia | D7: na Shabu Model Comprehensive Centre | E7: ZBFgkyECWkA | F7: NASARAWA | G7: LAFIA | H7: 002/01/23/INP | L7: F | M7: 01-Jan-1998 | N7: 27 | O7: 25 - 29 | P7: 25 | Q7: 04-Jan-2023 | R7: Other | S7: 113802 | T7: Provider-initiated HIV testing and counseling | U7: INPATIENT | V7: No | W7: Individual | X7: Other | Y7: Married | Z7: 4 | AB7: No | AE7: No | AF7: Yes | AG7: No | AH7: Yes | AI7: Yes | AJ7: Yes | AK7: No | AL7: Yes | AM7: Yes | AN7: No | AO7: No | AP7: Yes | AQ7: Yes | AR7: No | AS7: Yes | AT7: No | AU7: Yes | AV7: No | AW7: No | AX7: 2 | AY7: No | AZ7: Yes | BA7: No | BB7: 1 | BC7: 3 | BD7: NON-REACTIVE | BE7: 44930 | BJ7: Negative | BZ7: Previously tested negative | CA7: Yes | CB7: Yes | CC7: Yes | CD7: No | CE7: No | CI7: No | CJ7: Yes | CK7: Yes | CL7: Yes | CM7: Yes | CN7: No | CO7: No | CP7: No | CR7: 04-Jan-2023
A8: IHVN | B8: Nasarawa | C8: Lafia | D8: na Shabu Model Comprehensive Centre | E8: ZBFgkyECWkA | F8: NASARAWA | G8: LAFIA | H8: 004/1/23/VCT | L8: M | M8: 01-Jan-1993 | N8: 32 | O8: 30 - 34 | P8: 30 | Q8: 05-Jan-2023 | R8: Voluntary counseling and testing program | S8: 113807 | T8: Voluntary counseling and testing center | V8: No | W8: Individual | X8: SELF | Y8: Married | Z8: 2 | AA8: 1 | AB8: No | AE8: No | AF8: Yes | AH8: No | AI8: Yes | AJ8: Yes | AK8: Yes | AL8: Yes | AM8: Yes | AN8: No | AO8: No | AP8: No | AQ8: Yes | AR8: No | AS8: Yes | AT8: Yes | AU8: Yes | AV8: No | AW8: No | AX8: 3 | BA8: Yes | BB8: 1 | BC8: 2 | BD8: NON-REACTIVE | BE8: 44931 | BJ8: Negative | BZ8: Previously tested negative | CA8: Yes | CB8: Yes | CC8: Yes | CD8: No | CE8: No | CI8: No | CJ8: Yes | CK8: Yes | CL8: Yes | CM8: Yes | CN8: No | CO8: No | CP8: No | CR8: 05-Jan-2023
A9: IHVN | B9: Nasarawa | C9: Lafia | D9: na Shabu Model Comprehensive Centre | E9: ZBFgkyECWkA | F9: NASARAWA | G9: LAFIA | H9: 001/01/23/VCT | L9: M | M9: 01-Jan-1983 | N9: 42 | O9: 40 - 44 | P9: 40 | Q9: 01-Jan-2023 | R9: Voluntary counseling and testing program | S9: 113804 | T9: Voluntary counseling and testing center | V9: No | W9: Individual | X9: SELF | Y9: Married | Z9: 4 | AA9: 1 | AB9: No | AE9: No | AF9: Yes | AH9: Yes | AI9: Yes | AJ9: Yes | AK9: Yes | AL9: Yes | AM9: Yes | AN9: No | AO9: No | AP9: No | AQ9: Yes | AR9: Yes | AS9: Yes | AT9: Yes | AU9: Yes | AV9: No | AW9: No | AX9: 3 | BA9: Yes | BB9: 1 | BC9: 3 | BD9: NON-REACTIVE | BE9: 44927 | BJ9: Negative | BZ9: Previously tested negative | CA9: Yes | CB9: Yes | CC9: Yes | CD9: No | CE9: No | CI9: No | CJ9: Yes | CK9: Yes | CL9: Yes | CM9: Yes | CN9: No | CO9: No | CP9: No | CR9: 01-Jan-2023
A10: IHVN | B10: Nasarawa | C10: Lafia | D10: na Shabu Model Comprehensive Centre | E10: ZBFgkyECWkA | F10: NASARAWA | G10: LAFIA | H10: 003/01/23/INP | L10: F | M10: 01-Jan-1993 | N10: 32 | O10: 30 - 34 | P10: 30 | Q10: 05-Jan-2023 | R10: Other | S10: 113803 | T10: Provider-initiated HIV testing and counseling | U10: INPATIENT | V10: No | W10: Individual | X10: Other | Y10: Married | Z10: 3 | AB10: No | AE10: No | AF10: Yes | AG10: No | AH10: Yes | AI10: Yes | AJ10: Yes | AK10: Yes | AL10: Yes | AM10: Yes | AN10: No | AO10: No | AP10: Yes | AQ10: Yes | AR10: No | AS10: No | AT10: No | AU10: Yes | AV10: No | AW10: No | AX10: 1 | AY10: No | AZ10: Yes | BA10: No | BB10: 1 | BC10: 3 | BD10: NON-REACTIVE | BE10: 44931 | BJ10: Negative | BZ10: Previously tested negative | CA10: Yes | CB10: Yes | CC10: Yes | CD10: No | CE10: No | CI10: No | CJ10: Yes | CK10: Yes | CL10: Yes | CM10: Yes | CN10: No | CO10: No | CP10: No | CR10: 05-Jan-2023
A11: IHVN | B11: Nasarawa | C11: Lafia | D11: na Shabu Model Comprehensive Centre | E11: ZBFgkyECWkA | F11: NASARAWA | G11: LAFIA | H11: 004/01/23/INP | L11: F | M11: 01-Jan-2003 | N11: 22 | O11: 20 - 24 | P11: 20 | Q11: 05-Jan-2023 | R11: Other | S11: 113805 | T11: Provider-initiated HIV testing and counseling | U11: INPATIENT | V11: Yes | W11: Individual | X11: Other | Y11: Married | Z11: 2 | AB11: No | AE11: No | AF11: No | AG11: No | AH11: Yes | AI11: Yes | AJ11: Yes | AK11: Yes | AL11: Yes | AM11: Yes | AN11: No | AO11: Yes | AP11: No | AQ11: Yes | AR11: No | AS11: No | AT11: No | AU11: Yes | AV11: No | AW11: No | AX11: 1 | AY11: No | AZ11: Yes | BA11: No | BB11: 1 | BC11: 3 | BD11: NON-REACTIVE | BE11: 44931 | BJ11: Negative | BZ11: Not previously tested | CA11: Yes | CB11: Yes | CC11: Yes | CD11: Yes | CE11: Yes | CI11: No | CJ11: Yes | CK11: Yes | CL11: Yes | CM11: No | CN11: Yes | CO11: Yes | CP11: No | CR11: 05-Jan-2023
A12: IHVN | B12: Nasarawa | C12: Lafia | D12: na Shabu Model Comprehensive Centre | E12: ZBFgkyECWkA | F12: NASARAWA | G12: LAFIA | H12: 005/01/23/INP | L12: M | M12: 01-Jan-1998 | N12: 27 | O12: 25 - 29 | P12: 25 | Q12: 06-Jan-2023 | R12: Other | S12: 113806 | T12: Provider-initiated HIV testing and counseling | U12: INPATIENT | V12: No | W12: Individual | X12: Other | Y12: Married | Z12: 3 | AA12: 1 | AB12: No | AE12: No | AF12: Yes | AH12: Yes | AI12: Yes | AJ12: Yes | AK12: Yes | AL12: Yes | AM12: Yes | AN12: No | AO12: No | AP12: Yes | AQ12: Yes | AR12: No | AS12: No | AT12: Yes | AU12: No | AV12: Yes | AW12: No | AX12: 2 | BA12: No | BB12: 0 | BC12: 3 | BD12: NON-REACTIVE | BE12: 44932 | BJ12: Negative | BZ12: Previously tested negative | CA12: Yes | CB12: Yes | CC12: Yes | CD12: No | CE12: No | CI12: No | CJ12: Yes | CK12: Yes | CL12: Yes | CM12: Yes | CN12: No | CO12: No | CP12: No | CR12: 06-Jan-2023
A13: IHVN | B13: Nasarawa | C13: Lafia | D13: na Shabu Model Comprehensive Centre | E13: ZBFgkyECWkA | F13: NASARAWA | G13: LAFIA | H13: 002/01/23/VCT | L13: M | M13: 01-Jan-1996 | N13: 29 | O13: 25 - 29 | P13: 27 | Q13: 02-Jan-2023 | R13: Voluntary counseling and testing program | S13: 113810 | T13: Voluntary counseling and testing center | V13: No | W13: Individual | X13: SELF | Y13: Married | Z13: 1 | AA13: 1 | AB13: No | AE13: No | AF13: Yes | AH13: Yes | AI13: Yes | AJ13: Yes | AK13: Yes | AL13: Yes | AM13: Yes | AN13: No | AO13: Yes | AP13: No | AQ13: Yes | AR13: No | AS13: No | AT13: No | AU13: No | AV13: No | AW13: No | AX13: 0 | BA13: No | BB13: 0 | BC13: 3 | BD13: NON-REACTIVE | BE13: 44928 | BJ13: Negative | BZ13: Previously tested negative | CA13: Yes | CB13: Yes | CC13: Yes | CD13: No | CE13: No | CI13: No | CJ13: Yes | CK13: Yes | CL13: Yes | CM13: Yes | CN13: No | CO13: No | CP13: No | CR13: 02-Jan-2023
A14: IHVN | B14: Nasarawa | C14: Lafia | D14: na Shabu Model Comprehensive Centre | E14: ZBFgkyECWkA | F14: NASARAWA | G14: LAFIA | H14: 006/01/23/INP | L14: F | M14: 01-Jan-2001 | N14: 24 | O14: 20 - 24 | P14: 22 | Q14: 06-Jan-2023 | R14: Other | S14: 113808 | T14: Provider-initiated HIV testing and counseling | U14: INPATIENT | V14: Yes | W14: Individual | X14: Other | Y14: Never married | Z14: 0 | AB14: No | AE14: No | AF14: No | AG14: No | AH14: Yes | AI14: Yes | AJ14: Yes | AK14: Yes | AL14: Yes | AM14: Yes | AN14: No | AO14: Yes | AP14: No | AQ14: Yes | AR14: Yes | AS14: No | AT14: Yes | AU14: Yes | AV14: No | AW14: No | AX14: 2 | AY14: No | AZ14: Yes | BA14: No | BB14: 1 | BC14: 4 | BD14: NON-REACTIVE | BE14: 44932 | BJ14: Negative | BZ14: Not previously tested | CA14: Yes | CB14: Yes | CC14: Yes | CD14: Yes | CE14: Yes | CI14: No | CJ14: Yes | CK14: Yes | CL14: Yes | CM14: No | CN14: Yes | CO14: Yes | CP14: Yes | CR14: 06-Jan-2023
A15: IHVN | B15: Nasarawa | C15: Lafia | D15: na Shabu Model Comprehensive Centre | E15: ZBFgkyECWkA | F15: NASARAWA | G15: LAFIA | H15: 001/01/23/OPD | L15: M | M15: 01-Jan-2009 | N15: 16 | O15: 15 - 19 | P15: 14 | Q15: 01-Jan-2023 | R15: Outpatient department | S15: 113809 | T15: Provider-initiated HIV testing and counseling | V15: Yes | W15: Individual | X15: Other | Y15: Never married | Z15: 0 | AB15: No | AE15: No | AF15: No | AH15: Yes | AI15: Yes | AJ15: Yes | AK15: Yes | AL15: Yes | AM15: No | AN15: No | AO15: No | AP15: No | AQ15: No | AR15: No | AS15: Yes | AT15: No | AU15: Yes | AV15: No | AW15: No | AX15: 2 | BA15: No | BB15: 0 | BC15: 0 | BD15: NON-REACTIVE | BE15: 44927 | BJ15: Negative | BZ15: Not previously tested | CA15: Yes | CB15: Yes | CC15: Yes | CD15: No | CE15: No | CI15: No | CJ15: Yes | CK15: Yes | CL15: No | CM15: No | CN15: No | CO15: No | CP15: No | CR15: 01-Jan-2023
A16: IHVN | B16: Nasarawa | C16: Lafia | D16: na Shabu Model Comprehensive Centre | E16: ZBFgkyECWkA | F16: NASARAWA | G16: LAFIA | H16: 002/01/23/OPD | L16: M | M16: 01-Jan-1995 | N16: 30 | O16: 30 - 34 | P16: 28 | Q16: 01-Jan-2023 | R16: Outpatient department | S16: 113811 | T16: Provider-initiated HIV testing and counseling | V16: No | W16: Individual | X16: Other | Y16: Married | Z16: 1 | AA16: 1 | AB16: No | AE16: No | AF16: Yes | AH16: Yes | AI16: Yes | AJ16: Yes | AK16: Yes | AL16: Yes | AM16: Yes | AN16: No | AO16: No | AP16: Yes | AQ16: Yes | AR16: No | AS16: No | AT16: Yes | AU16: No | AV16: No | AW16: No | AX16: 1 | BA16: No | BB16: 0 | BC16: 3 | BD16: NON-REACTIVE | BE16: 44927 | BJ16: Negative | BZ16: Previously tested negative | CA16: Yes | CB16: Yes | CC16: Yes | CD16: No | CE16: No | CI16: No | CJ16: Yes | CK16: Yes | CL16: Yes | CM16: Yes | CN16: No | CO16: No | CP16: No | CR16: 01-Jan-2023
A17: IHVN | B17: Nasarawa | C17: Lafia | D17: na Shabu Model Comprehensive Centre | E17: ZBFgkyECWkA | F17: NASARAWA | G17: LAFIA | H17: 003/01/23/OPD | L17: F | M17: 01-Jan-1988 | N17: 37 | O17: 35 - 39 | P17: 35 | Q17: 02-Jan-2023 | R17: Outpatient department | S17: 113812 | T17: Provider-initiated HIV testing and counseling | V17: No | W17: Individual | X17: Other | Y17: Married | Z17: 3 | AB17: No | AE17: No | AF17: Yes | AG17: No | AH17: Yes | AI17: Yes | AJ17: Yes | AK17: Yes | AL17: Yes | AM17: Yes | AN17: No | AO17: No | AP17: Yes | AQ17: No | AR17: No | AS17: No | AT17: Yes | AU17: Yes | AV17: No | AW17: No | AX17: 2 | AY17: No | AZ17: Yes | BA17: No | BB17: 1 | BC17: 2 | BD17: NON-REACTIVE | BE17: 44928 | BJ17: Negative | BZ17: Previously tested negative | CA17: Yes | CB17: Yes | CC17: Yes | CD17: No | CE17: No | CI17: No | CJ17: Yes | CK17: Yes | CL17: Yes | CM17: Yes | CN17: No | CO17: No | CP17: No | CR17: 02-Jan-2023
A18: IHVN | B18: Nasarawa | C18: Lafia | D18: na Shabu Model Comprehensive Centre | E18: ZBFgkyECWkA | F18: NASARAWA | G18: LAFIA | H18: 003/01/23/VCT | L18: M | M18: 01-Jan-1983 | N18: 42 | O18: 40 - 44 | P18: 40 | Q18: 05-Jan-2023 | R18: Voluntary counseling and testing program | S18: 113816 | T18: Voluntary counseling and testing center | V18: No | W18: Individual | X18: SELF | Y18: Married | Z18: 4 | AA18: 1 | AB18: No | AE18: No | AF18: Yes | AH18: Yes | AI18: Yes | AJ18: Yes | AK18: Yes | AM18: Yes | AN18: No | AO18: No | AP18: Yes | AQ18: Yes | AR18: No | AS18: Yes | AT18: Yes | AU18: Yes | AV18: No | AW18: No | AX18: 3 | BA18: Yes | BB18: 1 | BC18: 3 | BD18: NON-REACTIVE | BE18: 44931 | BJ18: Negative | BZ18: Previously tested negative | CA18: Yes | CB18: Yes | CC18: Yes | CD18: No | CE18: No | CI18: No | CJ18: Yes | CK18: Yes | CL18: Yes | CM18: Yes | CN18: No | CO18: No | CP18: No | CR18: 05-Jan-2023
A19: IHVN | B19: Nasarawa | C19: Lafia | D19: na Shabu Model Comprehensive Centre | E19: ZBFgkyECWkA | F19: NASARAWA | G19: LAFIA | H19: 004/01/23/OPD | L19: M | M19: 01-Jan-2000 | N19: 25 | O19: 25 - 29 | P19: 23 | Q19: 02-Jan-2023 | R19: Outpatient department | S19: 113813 | T19: Provider-initiated HIV testing and counseling | V19: Yes | W19: Individual | X19: Other | Y19: Never married | Z19: 0 | AB19: No | AE19: No | AF19: No | AH19: Yes | AI19: Yes | AJ19: Yes | AK19: Yes | AL19: Yes | AM19: Yes | AN19: No | AO19: Yes | AP19: No | AQ19: Yes | AR19: Yes | AS19: Yes | AT19: No | AU19: Yes | AV19: No | AW19: No | AX19: 2 | BA19: No | BB19: 0 | BC19: 4 | BD19: NON-REACTIVE | BE19: 44928 | BJ19: Negative | BZ19: Not previously tested | CA19: Yes | CB19: Yes | CC19: Yes | CD19: Yes | CE19: Yes | CI19: No | CJ19: Yes | CK19: Yes | CL19: Yes | CM19: No | CN19: Yes | CO19: Yes | CP19: Yes | CR19: 02-Jan-2023
A20: IHVN | B20: Nasarawa | C20: Lafia | D20: na Shabu Model Comprehensive Centre | E20: ZBFgkyECWkA | F20: NASARAWA | G20: LAFIA | H20: 005/01/23/OPD | L20: F | M20: 01-Jan-1994 | N20: 31 | O20: 30 - 34 | P20: 29 | Q20: 03-Jan-2023 | R20: Outpatient department | S20: 113814 | T20: Provider-initiated HIV testing and counseling | V20: No | W20: Individual | X20: Other | Y20: Married | Z20: 1 | AB20: No | AE20: No | AF20: Yes | AG20: No | AH20: Yes | AI20: Yes | AJ20: Yes | AK20: Yes | AL20: Yes | AM20: Yes | AN20: No | AO20: No | AP20: Yes | AQ20: No | AR20: No | AS20: No | AT20: Yes | AU20: No | AV20: No | AW20: No | AX20: 1 | AY20: No | AZ20: Yes | BA20: No | BB20: 1 | BC20: 2 | BD20: NON-REACTIVE | BE20: 44929 | BJ20: Negative | BZ20: Previously tested negative | CA20: Yes | CB20: Yes | CC20: Yes | CD20: No | CE20: No | CI20: No | CJ20: Yes | CK20: Yes | CL20: Yes | CM20: Yes | CN20: No | CO20: No | CP20: No | CR20: 03-Jan-2023
A21: IHVN | B21: Nasarawa | C21: Lafia | D21: na Shabu Model Comprehensive Centre | E21: ZBFgkyECWkA | F21: NASARAWA | G21: LAFIA | H21: 006/01/23/OPD | L21: F | M21: 01-Jan-1994 | N21: 31 | O21: 30 - 34 | P21: 29 | Q21: 03-Jan-2023 | R21: Outpatient department | S21: 113815 | T21: Provider-initiated HIV testing and counseling | V21: Yes | W21: Individual | X21: Other | Y21: Married | Z21: 2 | AB21: No | AE21: No | AF21: No | AG21: No | AH21: Yes | AI21: Yes | AJ21: Yes | AK21: Yes | AL21: Yes | AM21: Yes | AN21: No | AO21: No | AP21: Yes | AQ21: Yes | AR21: No | AS21: No | AT21: No | AU21: No | AV21: No | AW21: No | AX21: 0 | AY21: Yes | AZ21: No | BA21: No | BB21: 1 | BC21: 3 | BD21: NON-REACTIVE | BE21: 44929 | BJ21: Negative | BZ21: Not previously tested | CA21: Yes | CB21: Yes | CC21: Yes | CD21: No | CE21: No | CI21: No | CJ21: Yes | CK21: Yes | CL21: Yes | CM21: Yes | CN21: No | CO21: No | CP21: No | CR21: 03-Jan-2023
A22: IHVN | B22: Nasarawa | C22: Lafia | D22: na Shabu Model Comprehensive Centre | E22: ZBFgkyECWkA | F22: NASARAWA | G22: LAFIA | H22: 007/01/23/OPD | L22: F | M22: 01-Jan-1992 | N22: 33 | O22: 30 - 34 | P22: 31 | Q22: 03-Jan-2023 | R22: Outpatient department | S22: 113817 | T22: Provider-initiated HIV testing and counseling | V22: No | W22: Individual | X22: Other | Y22: Married | Z22: 3 | AB22: No | AE22: No | AF22: Yes | AG22: No | AH22: Yes | AI22: Yes | AJ22: Yes | AK22: Yes | AL22: Yes | AM22: Yes | AN22: No | AO22: No | AP22: Yes | AQ22: Yes | AR22: No | AS22: No | AT22: No | AU22: Yes | AV22: No | AW22: No | AX22: 1 | AY22: No | AZ22: Yes | BA22: No | BB22: 1 | BC22: 3 | BD22: NON-REACTIVE | BE22: 44929 | BJ22: Negative | BZ22: Previously tested negative | CA22: Yes | CB22: Yes | CC22: Yes | CD22: No | CE22: No | CI22: No | CJ22: Yes | CK22: Yes | CL22: Yes | CM22: Yes | CN22: No | CO22: No | CP22: No | CR22: 03-Jan-2023
A23: IHVN | B23: Nasarawa | C23: Lafia | D23: na Shabu Model Comprehensive Centre | E23: ZBFgkyECWkA | F23: NASARAWA | G23: LAFIA | H23: 005/01/23/VCT | L23: M | M23: 01-Jan-1999 | N23: 26 | O23: 25 - 29 | P23: 24 | Q23: 07-Jan-2023 | R23: Voluntary counseling and testing program | S23: 113821 | T23: Voluntary counseling and testing center | V23: No | W23: Individual | X23: SELF | Y23: Never married | AB23: No | AE23: No | AF23: Yes | AH23: Yes | AI23: Yes | AJ23: Yes | AK23: Yes | AL23: Yes | AM23: Yes | AN23: No | AO23: Yes | AP23: No | AQ23: No | AR23: No | AS23: No | AT23: Yes | AU23: Yes | AV23: No | AW23: No | AX23: 2 | BA23: No | BB23: 0 | BC23: 2 | BD23: NON-REACTIVE | BE23: 44933 | BJ23: Negative | BZ23: Previously tested negative | CA23: Yes | CB23: Yes | CC23: Yes | CD23: No | CE23: No | CI23: No | CJ23: Yes | CK23: Yes | CL23: Yes | CM23: No | CN23: No | CO23: No | CP23: No | CR23: 07-Jan-2023
A24: IHVN | B24: Nasarawa | C24: Lafia | D24: na Shabu Model Comprehensive Centre | E24: ZBFgkyECWkA | F24: NASARAWA | G24: LAFIA | H24: 008/01/23/OPD | L24: F | M24: 01-Jan-2022 | N24: 3 | O24: 1 - 4 | P24: 1 | Q24: 04-Jan-2023 | R24: Outpatient department | S24: 113818 | T24: Provider-initiated HIV testing and counseling | V24: Yes | W24: Individual | X24: Other | Y24: Never married | AB24: No | AE24: No | AF24: No | AG24: No | AH24: Yes | AI24: Yes | AJ24: Yes | AK24: Yes | AL24: Yes | AM24: No | AN24: No | AO24: No | AP24: No | AQ24: No | AR24: No | AS24: No | AT24: Yes | AU24: Yes | AV24: No | AW24: No | AX24: 2 | AY24: No | AZ24: No | BA24: No | BB24: 0 | BC24: 0 | BD24: NON-REACTIVE | BE24: 44930 | BJ24: Negative | BZ24: Not previously tested | CA24: Yes | CB24: Yes | CC24: Yes | CD24: No | CE24: No | CI24: No | CJ24: Yes | CK24: Yes | CL24: No | CM24: No | CN24: No | CO24: No | CP24: No | CR24: 04-Jan-2023
A25: IHVN | B25: Nasarawa | C25: Lafia | D25: na Shabu Model Comprehensive Centre | E25: ZBFgkyECWkA | F25: NASARAWA | G25: LAFIA | H25: 009/01/23/OPD | L25: M | M25: 01-Jan-1988 | N25: 37 | O25: 35 - 39 | P25: 35 | Q25: 04-Jan-2023 | R25: Outpatient department | S25: 113819 | T25: Provider-initiated HIV testing and counseling | V25: No | W25: Individual | X25: Other | Y25: Married | Z25: 3 | AA25: 1 | AB25: No | AE25: No | AF25: Yes | AH25: Yes | AI25: Yes | AJ25: Yes | AK25: Yes | AL25: Yes | AM25: Yes | AN25: No | AO25: No | AP25: Yes | AQ25: Yes | AR25: No | AS25: No | AT25: No | AU25: Yes | AV25: No | AW25: No | AX25: 1 | BA25: No | BB25: 0 | BC25: 3 | BD25: NON-REACTIVE | BE25: 44930 | BJ25: Negative | BZ25: Previously tested negative | CA25: Yes | CB25: Yes | CC25: Yes | CD25: No | CE25: No | CI25: No | CJ25: Yes | CK25: Yes | CL25: Yes | CM25: Yes | CN25: No | CO25: No | CP25: No | CR25: 04-Jan-2023
A26: IHVN | B26: Nasarawa | C26: Lafia | D26: na Shabu Model Comprehensive Centre | E26: ZBFgkyECWkA | F26: NASARAWA | G26: LAFIA | H26: 010/01/23/OPD | L26: M | M26: 01-Jan-1993 | N26: 32 | O26: 30 - 34 | P26: 30 | Q26: 05-Jan-2023 | R26: Outpatient department | S26: 113820 | T26: Provider-initiated HIV testing and counseling | V26: No | W26: Individual | X26: Other | Y26: Married | Z26: 2 | AA26: 1 | AB26: No | AE26: No | AF26: Yes | AH26: Yes | AI26: Yes | AJ26: Yes | AK26: Yes | AL26: Yes | AM26: Yes | AN26: No | AO26: No | AP26: Yes | AQ26: Yes | AR26: No | AS26: No | AT26: Yes | AU26: No | AV26: No | AW26: No | AX26: 1 | BA26: No | BB26: 0 | BC26: 3 | BD26: NON-REACTIVE | BE26: 44931 | BJ26: Negative | BZ26: Previously tested negative | CA26: Yes | CB26: Yes | CC26: Yes | CD26: No | CE26: No | CI26: No | CJ26: Yes | CK26: Yes | CL26: Yes | CM26: Yes | CN26: No | CO26: No | CP26: No | CR26: 05-Jan-2023
A27: IHVN | B27: Nasarawa | C27: Lafia | D27: na Shabu Model Comprehensive Centre | E27: ZBFgkyECWkA | F27: NASARAWA | G27: LAFIA | H27: 011/1/23/OPD | L27: M | M27: 01-Jan-2003 | N27: 22 | O27: 20 - 24 | P27: 20 | Q27: 05-Jan-2023 | R27: Outpatient department | S27: 113822 | T27: Provider-initiated HIV testing and counseling | V27: Yes | W27: Individual | X27: Other | Y27: Never married | AB27: No | AE27: No | AF27: No | AH27: Yes | AI27: Yes | AJ27: Yes | AK27: Yes | AL27: Yes | AM27: Yes | AN27: No | AO27: Yes | AP27: No | AQ27: Yes | AR27: Yes | AS27: Yes | AT27: No | AU27: Yes | AV27: No | AW27: No | AX27: 2 | BA27: No | BB27: 0 | BC27: 4 | BD27: NON-REACTIVE | BE27: 44931 | BJ27: Negative | BZ27: Not previously tested | CA27: Yes | CB27: Yes | CC27: Yes | CD27: Yes | CE27: Yes | CI27: No | CJ27: Yes | CK27: Yes | CL27: Yes | CM27: No | CN27: Yes | CO27: Yes | CP27: Yes | CR27: 05-Jan-2023
A28: IHVN | B28: Nasarawa | C28: Lafia | D28: na Shabu Model Comprehensive Centre | E28: ZBFgkyECWkA | F28: NASARAWA | G28: LAFIA | H28: 012/1/23/OPD | L28: F | M28: 01-Jan-2020 | N28: 5 | O28: 5 - 9 | P28: 3 | Q28: 06-Jan-2023 | R28: Outpatient department | S28: 113823 | T28: Provider-initiated HIV testing and counseling | V28: Yes | W28: Individual | X28: Other | Y28: Never married | AB28: No | AE28: No | AF28: No | AG28: No | AH28: Yes | AI28: Yes | AJ28: Yes | AK28: Yes | AL28: Yes | AM28: No | AN28: No | AO28: No | AP28: No | AQ28: No | AR28: No | AS28: Yes | AT28: No | AU28: Yes | AV28: No | AW28: No | AX28: 2 | AY28: No | AZ28: No | BA28: No | BB28: 0 | BC28: 0 | BD28: NON-REACTIVE | BE28: 44932 | BJ28: Negative | BZ28: Not previously tested | CA28: Yes | CB28: Yes | CC28: Yes | CD28: No | CE28: No | CI28: No | CJ28: Yes | CK28: Yes | CL28: No | CM28: No | CN28: No | CO28: No | CP28: No | CR28: 05-Jan-2023
A29: IHVN | B29: Nasarawa | C29: Lafia | D29: na Shabu Model Comprehensive Centre | E29: ZBFgkyECWkA | F29: NASARAWA | G29: LAFIA | H29: 006/01/23/VCT | L29: M | M29: 01-Jan-1990 | N29: 35 | O29: 35 - 39 | P29: 33 | Q29: 07-Jan-2023 | R29: Voluntary counseling and testing program | S29: 113826 | T29: Voluntary counseling and testing center | V29: No | W29: Individual | X29: SELF | Y29: Married | Z29: 2 | AA29: 1 | AB29: No | AE29: No | AF29: Yes | AH29: Yes | AI29: Yes | AJ29: Yes | AK29: Yes | AL29: Yes | AM29: Yes | AN29: No | AO29: No | AP29: Yes | AQ29: Yes | AR29: No | AS29: No | AT29: Yes | AU29: Yes | AV29: No | AW29: No | AX29: 2 | BA29: Yes | BB29: 1 | BC29: 3 | BD29: NON-REACTIVE | BE29: 44933 | BJ29: Negative | BZ29: Previously tested negative | CA29: Yes | CB29: Yes | CC29: Yes | CD29: No | CE29: No | CI29: No | CJ29: Yes | CK29: Yes | CL29: Yes | CM29: Yes | CN29: No | CO29: No | CP29: No | CR29: 07-Jan-2023
A30: IHVN | B30: Nasarawa | C30: Lafia | D30: na Shabu Model Comprehensive Centre | E30: ZBFgkyECWkA | F30: NASARAWA | G30: LAFIA | H30: 013/1/23/OPD | L30: M | M30: 01-Jan-1953 | N30: 72 | O30: 50+ | P30: 70 | Q30: 06-Jan-2023 | R30: Outpatient department | S30: 113824 | T30: Provider-initiated HIV testing and counseling | V30: No | W30: Individual | X30: Other | Y30: Married | Z30: 8 | AA30: 1 | AB30: No | AE30: No | AF30: Yes | AH30: Yes | AI30: Yes | AJ30: Yes | AK30: Yes | AL30: Yes | AM30: Yes | AN30: No | AO30: No | AP30: Yes | AQ30: Yes | AR30: No | AS30: No | AT30: Yes | AU30: Yes | AV30: No | AW30: No | AX30: 2 | BA30: No | BB30: 0 | BC30: 3 | BD30: NON-REACTIVE | BE30: 44932 | BJ30: Negative | BZ30: Previously tested negative | CA30: Yes | CB30: Yes | CC30: Yes | CD30: No | CE30: No | CI30: No | CJ30: Yes | CK30: Yes | CL30: Yes | CM30: Yes | CN30: No | CO30: No | CP30: No | CR30: 06-Jan-2023
A31: IHVN | B31: Nasarawa | C31: Lafia | D31: na Shabu Model Comprehensive Centre | E31: ZBFgkyECWkA | F31: NASARAWA | G31: LAFIA | H31: 014/1/23/OPD | L31: F | M31: 01-Jan-1993 | N31: 32 | O31: 30 - 34 | P31: 30 | Q31: 06-Jan-2023 | R31: Outpatient department | S31: 113825 | T31: Provider-initiated HIV testing and counseling | V31: No | W31: Individual | X31: Other | Y31: Married | Z31: 3 | AB31: No | AE31: No | AF31: Yes | AG31: No | AH31: Yes | AI31: Yes | AJ31: Yes | AK31: Yes | AL31: Yes | AM31: Yes | AN31: No | AO31: No | AP31: Yes | AQ31: Yes | AR31: No | AS31: No | AT31: Yes | AU31: Yes | AV31: No | AW31: No | AX31: 2 | AY31: No | AZ31: Yes | BA31: No | BB31: 1 | BC31: 3 | BD31: NON-REACTIVE | BE31: 44932 | BJ31: Negative | BZ31: Previously tested negative | CA31: Yes | CB31: Yes | CC31: Yes | CD31: No | CE31: No | CI31: No | CJ31: Yes | CK31: Yes | CL31: Yes | CM31: Yes | CN31: No | CO31: No | CP31: No | CR31: 06-Jan-2023
A32: IHVN | B32: Nasarawa | C32: Lafia | D32: na Shabu Model Comprehensive Centre | E32: ZBFgkyECWkA | F32: NASARAWA | G32: LAFIA | H32: 018/01/23/OPD | L32: F | M32: 01-Jan-1991 | N32: 34 | O32: 30 - 34 | P32: 32 | Q32: 07-Jan-2023 | R32: Outpatient department | S32: 113828 | T32: Provider-initiated HIV testing and counseling | V32: No | W32: Individual | X32: Other | Y32: Married | Z32: 2 | AB32: No | AE32: No | AF32: Yes | AG32: No | AH32: Yes | AI32: Yes | AJ32: Yes | AK32: Yes | AL32: Yes | AM32: Yes | AN32: No | AO32: No | AP32: Yes | AQ32: Yes | AR32: No | AS32: Yes | AT32: No | AU32: Yes | AV32: No | AW32: No | AX32: 2 | AY32: No | AZ32: Yes | BA32: No | BB32: 1 | BC32: 3 | BD32: NON-REACTIVE | BE32: 44933 | BJ32: Negative | BZ32: Previously tested negative | CA32: Yes | CB32: Yes | CC32: Yes | CD32: No | CE32: No | CI32: No | CJ32: Yes | CK32: Yes | CL32: Yes | CM32: Yes | CN32: No | CO32: No | CP32: No | CR32: 07-Jan-2023
A33: IHVN | B33: Nasarawa | C33: Lafia | D33: na Shabu Model Comprehensive Centre | E33: ZBFgkyECWkA | F33: NASARAWA | G33: LAFIA | H33: 015/01/23/OPD | L33: F | M33: 01-Jan-2005 | N33: 20 | O33: 20 - 24 | P33: 18 | Q33: 07-Jan-2023 | R33: Outpatient department | S33: 113832 | T33: Provider-initiated HIV testing and counseling | V33: Yes | W33: Individual | X33: Outpatient department | Y33: Never married | AE33: No | AF33: No | AG33: No | AH33: Yes | AI33: Yes | AJ33: Yes | AK33: Yes | AL33: Yes | AM33: No | AN33: No | AO33: No | AP33: No | AQ33: No | AR33: No | AS33: Yes | AT33: Yes | AU33: Yes | AV33: No | AW33: No | AX33: 3 | AY33: No | AZ33: No | BA33: No | BB33: 0 | BC33: 0 | BD33: NON-REACTIVE | BE33: 44933 | BJ33: Negative | BZ33: Not previously tested | CA33: Yes | CB33: Yes | CC33: Yes | CD33: No | CE33: No | CI33: No | CJ33: Yes | CK33: Yes | CL33: No | CM33: No | CN33: No | CO33: No | CP33: No | CR33: 07-Jan-2023
A34: IHVN | B34: Nasarawa | C34: Lafia | D34: na Shabu Model Comprehensive Centre | E34: ZBFgkyECWkA | F34: NASARAWA | G34: LAFIA | H34: 019/01/23/OPD | L34: F | M34: 01-Jan-1991 | N34: 34 | O34: 30 - 34 | P34: 32 | Q34: 07-Jan-2023 | R34: Outpatient department | S34: 113830 | T34: Provider-initiated HIV testing and counseling | V34: Yes | W34: Individual | X34: Other | Y34: Married | Z34: 4 | AB34: No | AE34: No | AF34: No | AG34: No | AH34: Yes | AI34: Yes | AJ34: Yes | AK34: Yes | AL34: Yes | AM34: Yes | AN34: No | AO34: No | AP34: Yes | AQ34: Yes | AR34: No | AS34: No | AT34: Yes | AU34: Yes | AV34: No | AW34: No | AX34: 2 | AY34: Yes | AZ34: No | BA34: No | BB34: 1 | BC34: 3 | BD34: NON-REACTIVE | BE34: 44933 | BJ34: Negative | BZ34: Not previously tested | CA34: Yes | CB34: Yes | CC34: Yes | CD34: No | CE34: No | CI34: No | CJ34: Yes | CK34: Yes | CL34: Yes | CM34: Yes | CN34: No | CO34: No | CP34: No | CR34: 07-Jan-2023
A35: IHVN | B35: Nasarawa | C35: Lafia | D35: na Shabu Model Comprehensive Centre | E35: ZBFgkyECWkA | F35: NASARAWA | G35: LAFIA | H35: 020/01/23/OPD | L35: F | M35: 01-Jan-2005 | N35: 20 | O35: 20 - 24 | P35: 18 | Q35: 08-Jan-2023 | R35: Outpatient department | S35: 113833 | T35: Provider-initiated HIV testing and counseling | V35: No | W35: Individual | X35: Other | Y35: Never married | AB35: No | AE35: No | AF35: No | AG35: No | AH35: Yes | AI35: Yes | AJ35: Yes | AK35: Yes | AL35: Yes | AM35: No | AN35: No | AO35: No | AP35: No | AQ35: No | AR35: No | AS35: Yes | AT35: No | AU35: Yes | AV35: No | AW35: No | AX35: 2 | AY35: No | AZ35: Yes | BA35: No | BB35: 1 | BC35: 0 | BD35: NON-REACTIVE | BE35: 44934 | BJ35: Negative | BZ35: Not previously tested | CA35: Yes | CB35: Yes | CC35: Yes | CD35: No | CE35: No | CI35: No | CJ35: Yes | CK35: Yes | CL35: No | CM35: No | CN35: No | CO35: No | CP35: No | CR35: 08-Jan-2023
A36: IHVN | B36: Nasarawa | C36: Lafia | D36: na Shabu Model Comprehensive Centre | E36: ZBFgkyECWkA | F36: NASARAWA | G36: LAFIA | H36: 016/01/23/OPD | L36: M | M36: 01-Jan-1998 | N36: 27 | O36: 25 - 29 | P36: 25 | Q36: 11-Jan-2023 | R36: Outpatient department | S36: 113834 | T36: Provider-initiated HIV testing and counseling | V36: Yes | W36: Individual | X36: Outpatient department | Y36: Never married | AE36: No | AF36: No | AH36: Yes | AI36: Yes | AJ36: Yes | AK36: Yes | AL36: Yes | AM36: Yes | AN36: No | AO36: Yes | AP36: No | AQ36: No | AR36: Yes | AS36: No | AT36: Yes | AU36: Yes | AV36: No | AW36: No | AX36: 2 | BA36: No | BB36: 0 | BC36: 3 | BD36: NON-REACTIVE | BE36: 44937 | BJ36: Negative | BZ36: Not previously tested | CA36: Yes | CB36: Yes | CC36: Yes | CD36: No | CE36: Yes | CI36: No | CJ36: Yes | CK36: Yes | CL36: Yes | CM36: No | CN36: Yes | CO36: Yes | CP36: Yes | CR36: 11-Jan-2023
A37: IHVN | B37: Nasarawa | C37: Lafia | D37: na Shabu Model Comprehensive Centre | E37: ZBFgkyECWkA | F37: NASARAWA | G37: LAFIA | H37: 021/01/23/OPD | L37: F | M37: 01-Jan-1996 | N37: 29 | O37: 25 - 29 | P37: 27 | Q37: 08-Jan-2023 | R37: Outpatient department | S37: 113836 | T37: Provider-initiated HIV testing and counseling | V37: Yes | W37: Individual | X37: Other | Y37: Married | Z37: 1 | AB37: No | AE37: No | AF37: Yes | AG37: No | AH37: Yes | AI37: Yes | AJ37: Yes | AK37: Yes | AL37: Yes | AM37: Yes | AN37: No | AO37: No | AP37: Yes | AQ37: No | AR37: No | AS37: No | AT37: Yes | AU37: Yes | AV37: No | AW37: No | AX37: 2 | AY37: No | AZ37: Yes | BA37: No | BB37: 1 | BC37: 2 | BD37: NON-REACTIVE | BE37: 44934 | BJ37: Negative | BZ37: Previously tested negative | CA37: Yes | CB37: Yes | CC37: Yes | CD37: No | CE37: No | CI37: No | CJ37: Yes | CK37: Yes | CL37: Yes | CM37: Yes | CN37: No | CO37: No | CP37: No | CR37: 08-Jan-2023
A38: IHVN | B38: Nasarawa | C38: Lafia | D38: na Shabu Model Comprehensive Centre | E38: ZBFgkyECWkA | F38: NASARAWA | G38: LAFIA | H38: 022/01/23/OPD | L38: M | M38: 01-Jan-2006 | N38: 19 | O38: 15 - 19 | P38: 17 | Q38: 09-Jan-2023 | R38: Outpatient department | S38: 113837 | T38: Provider-initiated HIV testing and counseling | V38: Yes | W38: Individual | X38: Other | Y38: Never married | AB38: No | AE38: No | AF38: No | AH38: Yes | AI38: Yes | AJ38: Yes | AK38: Yes | AL38: Yes | AM38: No | AN38: No | AO38: No | AP38: No | AQ38: No | AR38: No | AS38: Yes | AT38: No | AU38: Yes | AV38: No | AW38: No | AX38: 2 | BA38: No | BB38: 0 | BC38: 0 | BD38: NON-REACTIVE | BE38: 44935 | BJ38: Negative | BZ38: Not previously tested | CA38: Yes | CB38: Yes | CC38: Yes | CD38: No | CE38: No | CI38: No | CJ38: Yes | CK38: Yes | CL38: No | CM38: No | CN38: No | CO38: No | CP38: No | CR38: 09-Jan-2023
A39: IHVN | B39: Nasarawa | C39: Lafia | D39: na Shabu Model Comprehensive Centre | E39: ZBFgkyECWkA | F39: NASARAWA | G39: LAFIA | H39: 017/01/23/OPD | L39: F | M39: 01-Jan-2001 | N39: 24 | O39: 20 - 24 | P39: 22 | Q39: 11-Jan-2023 | R39: Outpatient department | S39: 113840 | T39: Provider-initiated HIV testing and counseling | V39: Yes | W39: Individual | X39: Outpatient department | Y39: Never married | AE39: No | AF39: No | AG39: No | AH39: Yes | AI39: Yes | AJ39: Yes | AK39: Yes | AL39: Yes | AM39: Yes | AN39: No | AO39: Yes | AP39: No | AQ39: No | AR39: Yes | AS39: Yes | AT39: Yes | AU39: Yes | AV39: No | AW39: No | AX39: 3 | AY39: No | AZ39: No | BA39: No | BB39: 0 | BC39: 3 | BD39: NON-REACTIVE | BE39: 44937 | BJ39: Negative | BZ39: Not previously tested | CA39: Yes | CB39: Yes | CC39: Yes | CD39: No | CE39: Yes | CI39: No | CJ39: Yes | CK39: Yes | CL39: Yes | CM39: No | CN39: Yes | CO39: Yes | CP39: Yes | CR39: 11-Jan-2023
A40: IHVN | B40: Nasarawa | C40: Lafia | D40: na Shabu Model Comprehensive Centre | E40: ZBFgkyECWkA | F40: NASARAWA | G40: LAFIA | H40: 023/01/23/OPD | L40: F | M40: 01-Jan-1933 | N40: 92 | O40: 50+ | P40: 90 | Q40: 10-Jan-2023 | R40: Outpatient department | S40: 113839 | T40: Provider-initiated HIV testing and counseling | V40: No | W40: Individual | X40: Other | Y40: Married | Z40: 9 | AB40: No | AE40: No | AF40: Yes | AG40: No | AH40: Yes | AI40: Yes | AJ40: Yes | AK40: Yes | AL40: Yes | AM40: Yes | AN40: No | AO40: Yes | AP40: Yes | AQ40: Yes | AR40: No | AS40: Yes | AT40: No | AU40: Yes | AV40: No | AW40: No | AX40: 2 | AY40: No | AZ40: Yes | BA40: No | BB40: 1 | BC40: 4 | BD40: NON-REACTIVE | BE40: 44936 | BJ40: Negative | BZ40: Previously tested negative | CA40: Yes | CB40: Yes | CC40: Yes | CD40: No | CE40: No | CI40: No | CJ40: Yes | CK40: Yes | CL40: Yes | CM40: Yes | CN40: No | CO40: No | CP40: No | CR40: 10-Jan-2023
...

Sheet Gen ANC
A1: DatimCode | B1: ANCNo | C1: PepfarID | D1: HospID | E1: Sex | F1: DOB | G1: AgeAtVisit | H1: VisitDate | I1: VisitID | J1: DateOfLastMenstralPeriod | K1: GestationAgeWeeks | L1: Gravida | M1: ExpectedDeliveryDate | N1: Parity | O1: Losses | P1: WomanTestedForSyphilis | Q1: SyphilisTestDate | R1: SyphilisTestResult | S1: TreatedForSyphilis | T1: SyphilisTreatmentDate | U1: ReferredSyphilisPositiveClient | V1: HepatitisBTest | W1: HepatitisCTest | X1: FacilityReferredTo | Y1: KeyPopulation | Z1: KPType | AA1: HTSRegisterDate | AB1: HIVRegisterSetting | AC1: PreviouslyKnownHIVPositive | AD1: DatePreviouslyTestedHIVPositive | AE1: ResultOfHIVTest | AF1: HIVReTesting | AG1: PartnerTestingDate | AH1: PartnerPretestCounseled | AI1: PartnerAcceptsHIVTest | AJ1: PartnerHIVTestStatus | AK1: PartnerPostTestCounseledReceivedResults | AL1: PartnerHBVStatus | AM1: PartnerHCVStatus | AN1: PartnerSyphilisStatus | AO1: PartnerReferralTo | AP1: DeliveryDate | AQ1: TimeofHIVDiagnosesDeliveryRegister | AR1: GestationAgeWeeksAtDelivery | AS1: HepatitisBAtDelivery | AT1: HepatitisCAtDelivery | AU1: CurrentlyTakingARV | AV1: ARTStartedInLabourAndDeliveryWard | AW1: ModeOfDelivery | AX1: MaternalOutcome | AY1: NumberOfChildren | AZ1: ChildOutcomeAtDelivery
A2: ZBFgkyECWkA | B2: 0219/04/25/Anc | C2: NAS05400719 | E2: F | F2: 31-Dec-1986 | G2: 38 | H2: 16-Apr-2025 | I2: 142408 | J2: 01-Nov-2024 | K2: 24 | L2: 6 | M2: 08-Aug-2025 | N2: 5 | O2: 5 | P2: Yes | Q2: 16-Apr-2025 | R2: NON-REACTIVE | V2: Negative | W2: Negative | AA2: 16-Apr-2025 | AC2: Yes | AE2: Positive
A3: ZBFgkyECWkA | B3: 0111/2/25/ANC | C3: NAS05400486 | E3: F | F3: 08-Dec-1982 | G3: 42 | H3: 20-Feb-2025 | I3: 139323 | J3: 13-Oct-2024 | K3: 19 | L3: 10 | M3: 20-Jul-2025 | N3: 3 | O3: 3 | P3: Yes | Q3: 20-Feb-2025 | R3: NON-REACTIVE | V3: Negative | W3: Negative | AA3: 20-Feb-2025 | AB3: Seroconverted to HIV-Positive | AC3: Yes | AD3: 19-Apr-2011 | AE3: Positive | AF3: Seroconverted to HIV-Positive
A4: ZBFgkyECWkA | B4: 0406/12/23/ANC | C4: NAS05401904 | E4: F | F4: 01-Jan-1993 | G4: 30 | H4: 04-Dec-2023 | I4: 128036 | J4: 15-Jul-2023 | K4: 20 | L4: 2 | M4: 20-Apr-2024 | N4: 1 | O4: 1 | P4: Yes | Q4: 04-Feb-2024 | R4: NON-REACTIVE | AA4: 04-Dec-2023 | AC4: Yes | AD4: 14-Jun-2013
A5: ZBFgkyECWkA | B5: 0020/1/24/ANC | C5: NAS05402246 | E5: F | F5: 01-Jan-1993 | G5: 31 | H5: 15-Jan-2024 | I5: 129071 | J5: 30-Jul-2023 | K5: 29 | L5: 1 | M5: 05-May-2024 | N5: 0 | O5: 0 | P5: Yes | Q5: 15-Jan-2024 | R5: NON-REACTIVE | V5: Negative | W5: Negative | AA5: 15-Dec-2023 | AB5: Seroconverted to HIV-Positive | AC5: Yes | AD5: 24-Oct-2013 | AE5: Positive | AF5: Seroconverted to HIV-Positive
A6: ZBFgkyECWkA | B6: 0141/3/25/ANC | C6: NAS05403637 | E6: F | F6: 01-Jan-1997 | G6: 28 | H6: 06-Mar-2025 | I6: 140070 | J6: 15-Feb-2025 | K6: 3 | L6: 1 | M6: 22-Nov-2025 | N6: 0 | O6: 0 | P6: Yes | Q6: 06-Mar-2025 | R6: NON-REACTIVE | V6: Negative | W6: Negative | AA6: 06-Mar-2025 | AC6: Yes | AD6: 24-Feb-2016 | AE6: Positive
A7: ZBFgkyECWkA | B7: 0300/9/24/ANC | C7: NAS05403736 | E7: F | F7: 01-Jan-1996 | G7: 28 | H7: 02-Sep-2024 | I7: 134446 | J7: 15-Jan-2024 | K7: 33 | L7: 5 | M7: 21-Oct-2024 | N7: 3 | O7: 3 | P7: Yes | Q7: 02-Sep-2024 | R7: NON-REACTIVE | V7: Negative | W7: Negative | AA7: 02-Sep-2024 | AC7: Yes | AD7: 05-Apr-2016 | AE7: Positive
A8: ZBFgkyECWkA | B8: 0052/2/24/ANC | C8: NAS05403777 | E8: F | F8: 01-Jan-1996 | G8: 28 | H8: 08-Feb-2024 | I8: 129076 | J8: 17-Aug-2023 | K8: 25 | L8: 7 | M8: 23-May-2024 | N8: 5 | O8: 5 | P8: Yes | Q8: 08-Feb-2024 | R8: NON-REACTIVE | V8: Negative | W8: Negative | AA8: 08-Feb-2024 | AC8: Yes | AD8: 24-Mar-2016 | AE8: Positive
A9: ZBFgkyECWkA | B9: 0047/2/24/ANC | C9: NAS05404282 | E9: F | F9: 14-Aug-1996 | G9: 27 | H9: 08-Feb-2024 | I9: 129075 | J9: 19-Nov-2023 | K9: 12 | L9: 1 | M9: 25-Aug-2024 | N9: 0 | O9: 0 | P9: Yes | Q9: 08-Feb-2024 | R9: NON-REACTIVE | V9: Negative | W9: Negative | AA9: 08-Feb-2024 | AC9: Yes | AD9: 21-Aug-2017 | AE9: Positive
A10: ZBFgkyECWkA | B10: 0307/9/24/ANC | C10: NAS05404130 | E10: F | F10: 01-Jan-1997 | G10: 27 | H10: 05-Sep-2024 | I10: 134702 | J10: 02-Jul-2024 | K10: 9 | L10: 6 | M10: 08-Apr-2025 | N10: 4 | O10: 4 | P10: Yes | Q10: 05-Sep-2024 | R10: NON-REACTIVE | V10: Negative | W10: Negative | AA10: 05-Sep-2024 | AC10: Yes | AD10: 09-Feb-2017 | AE10: Positive
A11: ZBFgkyECWkA | B11: 0103/2/25/ANC | C11: NAS05404423 | E11: F | F11: 03-Jul-2002 | G11: 22 | H11: 18-Feb-2025 | I11: 139311 | J11: 06-Nov-2024 | K11: 15 | L11: 1 | M11: 13-Aug-2025 | N11: 0 | O11: 0 | P11: Yes | Q11: 17-Feb-2025 | R11: NON-REACTIVE | V11: Negative | W11: Negative | AA11: 18-Feb-2025 | AB11: Seroconverted to HIV-Positive | AC11: Yes | AD11: 01-Feb-2018 | AE11: Positive | AF11: Seroconverted to HIV-Positive
A12: ZBFgkyECWkA | B12: 0223/7/24/ANC | C12: NAS05404485 | E12: F | F12: 01-Jan-1996 | G12: 28 | H12: 05-Jul-2024 | I12: 132453 | J12: 27-Jan-2024 | K12: 23 | L12: 1 | M12: 02-Nov-2024 | N12: 0 | O12: 0 | P12: Yes | Q12: 05-Jul-2024 | R12: NON-REACTIVE | V12: Negative | W12: Negative | AA12: 05-Jul-2024 | AC12: Yes | AD12: 08-May-2018 | AE12: Positive
A13: ZBFgkyECWkA | B13: 002/2/25/ANC | C13: NAS05404555 | E13: F | F13: 01-Jan-1990 | G13: 35 | H13: 12-Feb-2025 | I13: 139296 | J13: 26-Sep-2024 | K13: 20 | L13: 3 | M13: 03-Jul-2025 | N13: 1 | O13: 1 | P13: Yes | Q13: 12-Feb-2025 | R13: NON-REACTIVE | V13: Negative | W13: Negative | AA13: 12-Feb-2025 | AB13: Seroconverted to HIV-Positive | AC13: Yes | AD13: 30-Oct-2013 | AE13: Positive | AF13: Seroconverted to HIV-Positive
A14: ZBFgkyECWkA | B14: 011/01/25/ANC | C14: NAS05404732 | E14: F | F14: 01-Jan-1992 | G14: 33 | H14: 06-Jan-2025 | I14: 138319 | J14: 11-Oct-2024 | K14: 12 | L14: 2 | M14: 18-Jul-2025 | N14: 1 | O14: 1 | P14: Yes | Q14: 06-Jan-2025 | R14: NON-REACTIVE | V14: Negative
A15: ZBFgkyECWkA | B15: 2345/2/25/ANC | C15: NAS05405376 | E15: F | F15: 01-Jan-1996 | G15: 29 | H15: 18-Feb-2025 | I15: 139304 | J15: 28-Jul-2024 | K15: 29 | L15: 6 | M15: 04-May-2025 | N15: 2 | O15: 2 | P15: Yes | Q15: 18-Feb-2025 | R15: NON-REACTIVE | V15: Negative | W15: Negative | AA15: 18-Feb-2025 | AB15: Seroconverted to HIV-Positive | AC15: Yes | AD15: 13-Oct-2021 | AE15: Positive | AF15: Seroconverted to HIV-Positive
A16: ZBFgkyECWkA | B16: 001/1/23/ANC | E16: F | F16: 01-Jan-1995 | G16: 28 | H16: 04-Jan-2023 | I16: 114706 | J16: 28-Sep-2022 | K16: 14 | L16: 6 | M16: 05-Jul-2023 | N16: 5 | O16: 5 | P16: Yes | Q16: 04-Jan-2023 | R16: NON-REACTIVE | V16: Negative | W16: Negative | AA16: 04-Jan-2023 | AB16: Remained HIV Negative | AC16: Yes | AD16: 04-Jan-2023 | AE16: Negative | AF16: Remained HIV Negative
A17: ZBFgkyECWkA | B17: 002/1/23/ANC | E17: F | F17: 01-Jan-1999 | G17: 24 | H17: 04-Jan-2023 | I17: 114710 | J17: 05-Oct-2022 | K17: 13 | L17: 3 | M17: 12-Jul-2023 | N17: 2 | O17: 2 | P17: Yes | Q17: 04-Jan-2023 | R17: NON-REACTIVE | V17: Negative | W17: Negative | AA17: 04-Jan-2023 | AB17: Remained HIV Negative | AC17: Yes | AD17: 04-Jan-2023 | AE17: Negative | AF17: Remained HIV Negative
